<?xml version='1.0' encoding='utf-8'?>
<mujoco model="indoor_space_urdf">
  <compiler angle="radian" />

  <asset>
    <mesh name="room_base_link" content_type="model/stl" file="d:/Programming/RAMI_Project/indoor_space_urdf_description/meshes/base_link.stl" scale="0.001 0.001 0.001" />
    <mesh name="wall_1" content_type="model/stl" file="d:/Programming/RAMI_Project/indoor_space_urdf_description/meshes/wall_1.stl" scale="0.001 0.001 0.001" />
    <mesh name="door_1_1" content_type="model/stl" file="d:/Programming/RAMI_Project/indoor_space_urdf_description/meshes/door_1_1.stl" scale="0.001 0.001 0.001" />
    <mesh name="door_2_1" content_type="model/stl" file="d:/Programming/RAMI_Project/indoor_space_urdf_description/meshes/door_2_1.stl" scale="0.001 0.001 0.001" />
    <mesh name="latch_1_1" content_type="model/stl" file="d:/Programming/RAMI_Project/indoor_space_urdf_description/meshes/latch_1_1.stl" scale="0.001 0.001 0.001" />
    <mesh name="latch_2_1" content_type="model/stl" file="d:/Programming/RAMI_Project/indoor_space_urdf_description/meshes/latch_2_1.stl" scale="0.001 0.001 0.001" />
    <mesh name="door_handle_1_1" content_type="model/stl" file="d:/Programming/RAMI_Project/indoor_space_urdf_description/meshes/door_handle_1_1.stl" scale="0.001 0.001 0.001" />
    <mesh name="toggle_switch_case_living-room_1" content_type="model/stl" file="d:/Programming/RAMI_Project/indoor_space_urdf_description/meshes/toggle_switch_case_living-room_1.stl" scale="0.001 0.001 0.001" />
    <mesh name="toggle_switch_case_corridor_1" content_type="model/stl" file="d:/Programming/RAMI_Project/indoor_space_urdf_description/meshes/toggle_switch_case_corridor_1.stl" scale="0.001 0.001 0.001" />
    <mesh name="toggle_switch_H20_corridor-lamp_2_1" content_type="model/stl" file="d:/Programming/RAMI_Project/indoor_space_urdf_description/meshes/toggle_switch_H20_corridor-lamp_2_1.stl" scale="0.001 0.001 0.001" />
    <mesh name="door_handle_2_1" content_type="model/stl" file="d:/Programming/RAMI_Project/indoor_space_urdf_description/meshes/door_handle_2_1.stl" scale="0.001 0.001 0.001" />
    <mesh name="toggle_switch_H20_corridor-lamp_3_1" content_type="model/stl" file="d:/Programming/RAMI_Project/indoor_space_urdf_description/meshes/toggle_switch_H20_corridor-lamp_3_1.stl" scale="0.001 0.001 0.001" />
    <mesh name="toggle_switch_H20_corridor-lamp_4_1" content_type="model/stl" file="d:/Programming/RAMI_Project/indoor_space_urdf_description/meshes/toggle_switch_H20_corridor-lamp_4_1.stl" scale="0.001 0.001 0.001" />
    <mesh name="toggle_switch_case_kitchen_1" content_type="model/stl" file="d:/Programming/RAMI_Project/indoor_space_urdf_description/meshes/toggle_switch_case_kitchen_1.stl" scale="0.001 0.001 0.001" />
    <mesh name="toggle_switch_H80_kitchen-lamp_1_1" content_type="model/stl" file="d:/Programming/RAMI_Project/indoor_space_urdf_description/meshes/toggle_switch_H80_kitchen-lamp_1_1.stl" scale="0.001 0.001 0.001" />
    <mesh name="toggle_switch_H40_living-room-lamp_1_1" content_type="model/stl" file="d:/Programming/RAMI_Project/indoor_space_urdf_description/meshes/toggle_switch_H40_living-room-lamp_1_1.stl" scale="0.001 0.001 0.001" />
    <mesh name="toggle_switch_H40_living-room-lamp_2_1" content_type="model/stl" file="d:/Programming/RAMI_Project/indoor_space_urdf_description/meshes/toggle_switch_H40_living-room-lamp_2_1.stl" scale="0.001 0.001 0.001" />
    <mesh name="toggle_switch_H20_corridor-lamp_1_1" content_type="model/stl" file="d:/Programming/RAMI_Project/indoor_space_urdf_description/meshes/toggle_switch_H20_corridor-lamp_1_1.stl" scale="0.001 0.001 0.001" />
    <mesh name="toggle_switch_case_room_1_1" content_type="model/stl" file="d:/Programming/RAMI_Project/indoor_space_urdf_description/meshes/toggle_switch_case_room_1_1.stl" scale="0.001 0.001 0.001" />
    <mesh name="toggle_switch_H80_room-ramp_1_1" content_type="model/stl" file="d:/Programming/RAMI_Project/indoor_space_urdf_description/meshes/toggle_switch_H80_room-ramp_1_1.stl" scale="0.001 0.001 0.001" />
    <mesh name="key_switch_case_room_2_1" content_type="model/stl" file="d:/Programming/RAMI_Project/indoor_space_urdf_description/meshes/key_switch_case_room_2_1.stl" scale="0.001 0.001 0.001" />
    <mesh name="key_switch_room-ramp_2_1" content_type="model/stl" file="d:/Programming/RAMI_Project/indoor_space_urdf_description/meshes/key_switch_room-ramp_2_1.stl" scale="0.001 0.001 0.001" />
    <mesh name="ceiling_v1_1" content_type="model/stl" file="d:/Programming/RAMI_Project/indoor_space_urdf_description/meshes/ceiling_v1_1.stl" scale="0.001 0.001 0.001" />
  <texture name="tex_wood" type="2d" builtin="checker" rgb1="0.3 0.15 0.05" rgb2="0.2 0.1 0.02" width="512" height="512" mark="edge" markrgb="0.1 0.05 0.01" /><material name="mat_wood" texture="tex_wood" texrepeat="20 20" reflectance="0.1" /><material name="mat_lamp" rgba="0.95 0.95 0.5 1" emission="1.0" /><texture name="tex_qr" type="2d" builtin="checker" rgb1="0 0 0" rgb2="1 1 1" width="128" height="128" mark="none" /><material name="mat_qr" texture="tex_qr" texrepeat="5 5" emission="0.5" /><texture name="tex_qr_switch_case_1" type="cube" file="d:/Programming/RAMI_Project/indoor_space_urdf_description/meshes/qr_codes/switch_case_1.png" /><material name="mat_qr_switch_case_1" texture="tex_qr_switch_case_1" emission="0.5" /><texture name="tex_qr_switch_case_2" type="cube" file="d:/Programming/RAMI_Project/indoor_space_urdf_description/meshes/qr_codes/switch_case_2.png" /><material name="mat_qr_switch_case_2" texture="tex_qr_switch_case_2" emission="0.5" /><texture name="tex_qr_switch_case_3" type="cube" file="d:/Programming/RAMI_Project/indoor_space_urdf_description/meshes/qr_codes/switch_case_3.png" /><material name="mat_qr_switch_case_3" texture="tex_qr_switch_case_3" emission="0.5" /><texture name="tex_qr_switch_case_4" type="cube" file="d:/Programming/RAMI_Project/indoor_space_urdf_description/meshes/qr_codes/switch_case_4.png" /><material name="mat_qr_switch_case_4" texture="tex_qr_switch_case_4" emission="0.5" /><texture name="tex_qr_switch_case_5" type="cube" file="d:/Programming/RAMI_Project/indoor_space_urdf_description/meshes/qr_codes/switch_case_5.png" /><material name="mat_qr_switch_case_5" texture="tex_qr_switch_case_5" emission="0.5" /></asset>

  <worldbody>
    <geom type="mesh" mesh="room_base_link" material="mat_wood" />
    <geom type="mesh" mesh="wall_1" rgba="0.85 0.85 0.85 1" />
    <geom pos="0 0 0" quat="1 0 0 0" type="mesh" mesh="toggle_switch_case_living-room_1" rgba="0.6 0.6 0.6 1" />
    <geom pos="0 0 0" type="mesh" mesh="toggle_switch_case_corridor_1" rgba="0.6 0.6 0.6 1" />
    <geom pos="0 0 0" quat="1 0 0 0" type="mesh" mesh="toggle_switch_case_kitchen_1" rgba="0.6 0.6 0.6 1" />
    <geom pos="0 0 0" quat="1 0 0 0" type="mesh" mesh="toggle_switch_case_room_1_1" rgba="0.6 0.6 0.6 1" />
    <geom pos="0 0 0" type="mesh" mesh="key_switch_case_room_2_1" rgba="0.6 0.6 0.6 1" />
    <geom type="mesh" mesh="ceiling_v1_1" group="3" rgba="0.85 0.85 0.85 1" />
    <geom size="0.025 0.025 0.01" pos="2.5 1.5 5.45" type="box" material="mat_lamp" />
    <geom size="0.025 0.025 0.01" pos="10.5 1.5 5.45" type="box" material="mat_lamp" />
    <geom size="0.025 0.025 0.01" pos="18.5 1.5 5.45" type="box" material="mat_lamp" />
    <geom size="0.025 0.025 0.01" pos="18.5 5.5 5.45" type="box" material="mat_lamp" />
    <geom size="0.1 0.1 0.01" pos="5 8 5.45" type="box" material="mat_lamp" />
    <geom size="0.1 0.1 0.01" pos="13 8 5.45" type="box" material="mat_lamp" />
    <geom size="0.05 0.15 0.01" pos="11 16 5.45" type="box" material="mat_lamp" />
    <geom size="0.05 0.15 0.01" pos="15 16 5.45" type="box" material="mat_lamp" />
    <geom size="0.05 0.01" pos="3 15 4.6875" type="cylinder" material="mat_lamp" />
    <body name="door_1_1" pos="5.2 3.4 2.1">
      <inertial pos="-1.02357 -0.025 0.000844161" quat="0.707107 -0.000251454 -0.000251454 0.707107" mass="3205.02" diaginertia="5378.26 4258.48 1121.11" />
      <joint name="door_1_1_joint" pos="0 0 0" axis="0 0 1" range="-2.79253 0" actuatorfrcrange="-100 100" frictionloss="0.5" damping="2.0" />
      <geom pos="-5.2 -3.4 -2.1" quat="1 0 0 0" type="mesh" mesh="door_1_1" rgba="0.7 0.5 0.3 1" />
      <body name="latch_1_1" pos="1.325 -3.25 -0.29">
        <inertial pos="-3.37218 3.226 -0.08" quat="0.529897 0.529897 0.468198 0.468198" mass="0.630692" diaginertia="0.000296862 0.000208 0.000174138" />
        <joint name="latch_1_1_joint" pos="0 0 0" axis="1 0 0" type="slide" range="0 0.04" actuatorfrcrange="-100 100" frictionloss="0.5" damping="1.0" stiffness="50.0" springref="0" />
        <geom pos="-6.525 -0.15 -1.81" quat="1 0 0 0" type="mesh" mesh="latch_1_1" rgba="0.6 0.6 0.6 1" />
      </body>
      <body name="door_handle_1_1" pos="-1.8 -0.05 -0.595">
        <inertial pos="0.0174026 0.025 0.00083086" quat="0.495559 0.495559 -0.504402 0.504402" mass="7.30752" diaginertia="0.0511667 0.0392913 0.0191" />
        <joint name="door_handle_1_1_joint" pos="0 0 0" axis="0 1 0" range="0 0.785398" actuatorfrcrange="-100 100" frictionloss="0.1" damping="0.5" stiffness="50.0" springref="0" />
        <geom pos="-3.4 -3.35 -1.505" quat="1 0 0 0" type="mesh" mesh="door_handle_1_1" rgba="0.6 0.6 0.6 1" />
      </body>
    </body>
    <body name="door_2_1" pos="15.6 3.4 2.1">
      <inertial pos="-1.02357 -0.025 0.000844161" quat="0.707107 -0.000251454 -0.000251454 0.707107" mass="3205.02" diaginertia="5378.26 4258.48 1121.11" />
      <joint name="door_2_1_joint" pos="0 0 0" axis="0 0 1" range="-2.00713 0" actuatorfrcrange="-100 100" frictionloss="0.5" damping="2.0" />
      <geom pos="-15.6 -3.4 -2.1" quat="1 0 0 0" type="mesh" mesh="door_2_1" rgba="0.7 0.5 0.3 1" />
      <body name="latch_2_1" pos="1.325 -13.65 -0.29">
        <inertial pos="-3.3722 13.626 -0.08" quat="0.529897 0.529897 0.468198 0.468198" mass="0.630692" diaginertia="0.000296862 0.000208 0.000174138" />
        <joint name="latch_2_1_joint" pos="0 0 0" axis="1 0 0" type="slide" range="0 0.04" actuatorfrcrange="-100 100" frictionloss="0.5" damping="1.0" stiffness="50.0" springref="0" />
        <geom pos="-16.925 10.25 -1.81" quat="1 0 0 0" type="mesh" mesh="latch_2_1" rgba="0.6 0.6 0.6 1" />
      </body>
      <body name="door_handle_2_1" pos="-1.8 -0.05 -0.595">
        <inertial pos="0.0174026 0.025 0.00083086" quat="0.495559 0.495559 -0.504402 0.504402" mass="7.30752" diaginertia="0.0511667 0.0392913 0.0191" />
        <joint name="door_handle_2_1_joint" pos="0 0 0" axis="0 1 0" range="0 0.785398" actuatorfrcrange="-100 100" frictionloss="0.1" damping="0.5" stiffness="50.0" springref="0" />
        <geom pos="-13.8 -3.35 -1.505" quat="1 0 0 0" type="mesh" mesh="door_handle_2_1" rgba="0.6 0.6 0.6 1" />
      </body>
    </body>
    <body name="toggle_switch_H40_living-room-lamp_1_1" pos="11.6 10.015 1.26">
      <inertial pos="4.87775e-09 0.00158461 0.02" quat="0.5 0.5 0.5 0.5" mass="0.300252" diaginertia="0.000113 8.4e-05 5e-05" />
      <joint name="toggle_switch_H40_living-room-lamp_1_1_joint" pos="4.87775e-09 0.00158461 0.02" axis="0 0 1" range="-0.1309 0.1309" actuatorfrcrange="-100 100" frictionloss="0.2" damping="0.1" />
      <geom pos="-11.6 -10.015 -1.26" quat="1 0 0 0" type="mesh" mesh="toggle_switch_H40_living-room-lamp_1_1" rgba="0.6 0.6 0.6 1" />
    </body>
    <body name="toggle_switch_H40_living-room-lamp_2_1" pos="23.161 11.26 -8.665">
      <inertial pos="-11.561 -1.24342 9.985" quat="0.5 0.5 0.5 0.5" mass="0.300252" diaginertia="0.000113 8.4e-05 5e-05" />
      <joint name="toggle_switch_H40_living-room-lamp_2_1_joint" pos="-11.561 -1.24342 9.985" axis="0 0 1" range="-0.1309 0.1309" actuatorfrcrange="-100 100" frictionloss="0.2" damping="0.1" />
      <geom pos="-23.161 -11.26 8.665" quat="1 0 0 0" type="mesh" mesh="toggle_switch_H40_living-room-lamp_2_1" rgba="0.6 0.6 0.6 1" />
    </body>
    <body name="toggle_switch_H20_corridor-lamp_2_1" pos="18.14 20.746 0.75">
      <inertial pos="1.64347 -19.7458 0.94" quat="0.531491 0.466387 -0.531491 0.466387" mass="0.14938" diaginertia="4.2e-05 4.15242e-05 1.04758e-05" />
      <joint name="toggle_switch_H20_corridor-lamp_2_1_joint" pos="1.64347 -19.7458 0.94" axis="0 0 1" range="-0.1309 0.1309" actuatorfrcrange="-100 100" frictionloss="0.2" damping="0.1" />
      <geom pos="-18.14 -20.746 -0.75" quat="1 0 0 0" type="mesh" mesh="toggle_switch_H20_corridor-lamp_2_1" rgba="0.6 0.6 0.6 1" />
    </body>
    <body name="toggle_switch_H20_corridor-lamp_3_1" pos="18.14 20.746 0.75">
      <inertial pos="1.64347 -19.7458 0.96" quat="0.531491 0.466387 -0.531491 0.466387" mass="0.14938" diaginertia="4.2e-05 4.15242e-05 1.04758e-05" />
      <joint name="toggle_switch_H20_corridor-lamp_3_1_joint" pos="1.64347 -19.7458 0.96" axis="0 0 1" range="-0.1309 0.1309" actuatorfrcrange="-100 100" frictionloss="0.2" damping="0.1" />
      <geom pos="-18.14 -20.746 -0.75" quat="1 0 0 0" type="mesh" mesh="toggle_switch_H20_corridor-lamp_3_1" rgba="0.6 0.6 0.6 1" />
    </body>
    <body name="toggle_switch_H20_corridor-lamp_4_1" pos="18.14 20.746 0.75">
      <inertial pos="1.64347 -19.7458 0.98" quat="0.531491 0.466387 -0.531491 0.466387" mass="0.14938" diaginertia="4.2e-05 4.15242e-05 1.04758e-05" />
      <joint name="toggle_switch_H20_corridor-lamp_4_1_joint" pos="1.64347 -19.7458 0.98" axis="0 0 1" range="-0.1309 0.1309" actuatorfrcrange="-100 100" frictionloss="0.2" damping="0.1" />
      <geom pos="-18.14 -20.746 -0.75" quat="1 0 0 0" type="mesh" mesh="toggle_switch_H20_corridor-lamp_4_1" rgba="0.6 0.6 0.6 1" />
    </body>
    <body name="toggle_switch_H20_corridor-lamp_1_1" pos="19.785 1 1.66">
      <inertial pos="-0.0015251 0.000200788 0.01" quat="0.531491 0.466387 -0.531491 0.466387" mass="0.14938" diaginertia="4.2e-05 4.15242e-05 1.04758e-05" />
      <joint name="toggle_switch_H20_corridor-lamp_1_1_joint" pos="-0.0015251 0.000200788 0.01" axis="0 0 1" range="-0.1309 0.1309" actuatorfrcrange="-100 100" frictionloss="0.2" damping="0.1" />
      <geom pos="-19.785 -1 -1.66" quat="1 0 0 0" type="mesh" mesh="toggle_switch_H20_corridor-lamp_1_1" rgba="0.6 0.6 0.6 1" />
    </body>
    <body name="toggle_switch_H80_kitchen-lamp_1_1" pos="3.2 19.785 1.66">
      <inertial pos="-4.89003e-09 -0.00160762 0.04" quat="0.707107 0 0 0.707107" mass="0.601995" diaginertia="0.000466 0.000341 0.000168" />
      <joint name="toggle_switch_H80_kitchen-lamp_1_1_joint" pos="-4.89003e-09 -0.00160762 0.04" axis="0 0 -1" range="-0.1309 0.1309" actuatorfrcrange="-100 100" frictionloss="0.2" damping="0.1" />
      <geom pos="-3.2 -19.785 -1.66" quat="1 0 0 0" type="mesh" mesh="toggle_switch_H80_kitchen-lamp_1_1" rgba="0.6 0.6 0.6 1" />
    </body>
    <body name="toggle_switch_H80_room-ramp_1_1" pos="11.9 3.415 1.66">
      <inertial pos="0.000209841 0.00159386 0.04" quat="0.751303 0 0 0.659958" mass="0.601995" diaginertia="0.00046608 0.00034092 0.000168" />
      <joint name="toggle_switch_H80_room-ramp_1_1_joint" pos="0.000209841 0.00159386 0.04" axis="0 0 1" range="-0.1309 0.1309" actuatorfrcrange="-100 100" frictionloss="0.2" damping="0.1" />
      <geom pos="-11.9 -3.415 -1.66" quat="1 0 0 0" type="mesh" mesh="toggle_switch_H80_room-ramp_1_1" rgba="0.6 0.6 0.6 1" />
    </body>
    <body name="key_switch_room-ramp_2_1" pos="1.9 13.17 1.525">
      <inertial pos="-1.67759 -6.57 0.175" mass="0.146062" diaginertia="2.9e-05 1.7e-05 1.7e-05" />
      <joint name="key_switch_room-ramp_2_1_joint" pos="-1.67759 -6.57 0.175" axis="1 0 0" type="slide" range="0 0.01" actuatorfrcrange="-100 100" frictionloss="0.2" damping="0.5" stiffness="10.0" springref="0" />
      <geom pos="-1.9 -13.17 -1.525" type="mesh" mesh="key_switch_room-ramp_2_1" rgba="0.6 0.6 0.6 1" />
    </body>
  <light name="light_lamp_1" pos="2.5 1.5 5.430000000000001" dir="0 0 -1" directional="false" castshadow="true" diffuse="0.8 0.8 0.6" specular="0.2 0.2 0.2" attenuation="0.1 0.1 0.1" cutoff="45" exponent="10" /><light name="light_lamp_2" pos="10.5 1.5 5.430000000000001" dir="0 0 -1" directional="false" castshadow="true" diffuse="0.8 0.8 0.6" specular="0.2 0.2 0.2" attenuation="0.1 0.1 0.1" cutoff="45" exponent="10" /><light name="light_lamp_3" pos="18.5 1.5 5.430000000000001" dir="0 0 -1" directional="false" castshadow="true" diffuse="0.8 0.8 0.6" specular="0.2 0.2 0.2" attenuation="0.1 0.1 0.1" cutoff="45" exponent="10" /><light name="light_lamp_4" pos="18.5 5.5 5.430000000000001" dir="0 0 -1" directional="false" castshadow="true" diffuse="0.8 0.8 0.6" specular="0.2 0.2 0.2" attenuation="0.1 0.1 0.1" cutoff="45" exponent="10" /><light name="light_lamp_5" pos="5.0 8.0 5.430000000000001" dir="0 0 -1" directional="false" castshadow="true" diffuse="0.8 0.8 0.6" specular="0.2 0.2 0.2" attenuation="0.1 0.1 0.1" cutoff="45" exponent="10" /><light name="light_lamp_6" pos="13.0 8.0 5.430000000000001" dir="0 0 -1" directional="false" castshadow="true" diffuse="0.8 0.8 0.6" specular="0.2 0.2 0.2" attenuation="0.1 0.1 0.1" cutoff="45" exponent="10" /><light name="light_lamp_7" pos="11.0 16.0 5.430000000000001" dir="0 0 -1" directional="false" castshadow="true" diffuse="0.8 0.8 0.6" specular="0.2 0.2 0.2" attenuation="0.1 0.1 0.1" cutoff="45" exponent="10" /><light name="light_lamp_8" pos="15.0 16.0 5.430000000000001" dir="0 0 -1" directional="false" castshadow="true" diffuse="0.8 0.8 0.6" specular="0.2 0.2 0.2" attenuation="0.1 0.1 0.1" cutoff="45" exponent="10" /><light name="light_lamp_9" pos="3.0 15.0 4.6675" dir="0 0 -1" directional="false" castshadow="true" diffuse="0.8 0.8 0.6" specular="0.2 0.2 0.2" attenuation="0.1 0.1 0.1" cutoff="45" exponent="10" /><geom name="qr_switch_case_1" type="box" size="0.02 0.02 0.02" pos="11.600000002438875 10.016582305 1.4200000000000004" material="mat_qr_switch_case_1" /><geom name="qr_switch_case_2" type="box" size="0.02 0.02 0.02" pos="19.783471225 1.0002001969999996 1.83" material="mat_qr_switch_case_2" /><geom name="qr_switch_case_3" type="box" size="0.02 0.02 0.02" pos="3.19999999510997 19.78339238 1.8" material="mat_qr_switch_case_3" /><geom name="qr_switch_case_4" type="box" size="0.02 0.02 0.02" pos="11.900209841 3.41659386 1.8" material="mat_qr_switch_case_4" /><geom name="qr_switch_case_5" type="box" size="0.02 0.02 0.02" pos="0.22241 6.6 1.8" material="mat_qr_switch_case_5" /></worldbody>
</mujoco>