<?xml version='1.0' encoding='utf-8'?>
<mujoco model="robot_RAMI_v1_urdf">
  <compiler angle="radian" />

  <asset>
    <!-- Sensor Visualization Materials and Meshes -->
    <material name="vis_camera" rgba="1 1 0 0.3" emission="1" />
    <material name="vis_ultrasonic" rgba="0 0.5 1 0.3" emission="1" />
    <mesh name="visual_pyramid_head" content_type="model/stl" file="d:/Programming/RAMI_Project/robot_RAMI_v1_urdf_description/meshes/visual_pyramid.stl" scale="16.782 16.782 10" />
    <mesh name="visual_pyramid_gripper" content_type="model/stl" file="d:/Programming/RAMI_Project/robot_RAMI_v1_urdf_description/meshes/visual_pyramid.stl" scale="1.154 1.154 1" />
    <mesh name="visual_cone_us" content_type="model/stl" file="d:/Programming/RAMI_Project/robot_RAMI_v1_urdf_description/meshes/visual_cone.stl" scale="1.339 1.339 5" />

    <mesh name="base_link" content_type="model/stl" file="d:/Programming/RAMI_Project/robot_RAMI_v1_urdf_description/meshes/base_link.stl" scale="0.001 0.001 0.001" />
    <mesh name="weel_left_front_1" content_type="model/stl" file="d:/Programming/RAMI_Project/robot_RAMI_v1_urdf_description/meshes/weel_left_front_1.stl" scale="0.001 0.001 0.001" />
    <mesh name="weel_left_back_1" content_type="model/stl" file="d:/Programming/RAMI_Project/robot_RAMI_v1_urdf_description/meshes/weel_left_back_1.stl" scale="0.001 0.001 0.001" />
    <mesh name="weel_right_front_1" content_type="model/stl" file="d:/Programming/RAMI_Project/robot_RAMI_v1_urdf_description/meshes/weel_right_front_1.stl" scale="0.001 0.001 0.001" />
    <mesh name="weel_right_back_1" content_type="model/stl" file="d:/Programming/RAMI_Project/robot_RAMI_v1_urdf_description/meshes/weel_right_back_1.stl" scale="0.001 0.001 0.001" />
    <mesh name="pillar_link_1" content_type="model/stl" file="d:/Programming/RAMI_Project/robot_RAMI_v1_urdf_description/meshes/pillar_link_1.stl" scale="0.001 0.001 0.001" />
    <mesh name="lift_slide_link_1" content_type="model/stl" file="d:/Programming/RAMI_Project/robot_RAMI_v1_urdf_description/meshes/lift_slide_link_1.stl" scale="0.001 0.001 0.001" />
    <mesh name="rotation_link_1" content_type="model/stl" file="d:/Programming/RAMI_Project/robot_RAMI_v1_urdf_description/meshes/rotation_link_1.stl" scale="0.001 0.001 0.001" />
    <mesh name="arm_link_1_1" content_type="model/stl" file="d:/Programming/RAMI_Project/robot_RAMI_v1_urdf_description/meshes/arm_link_1_1.stl" scale="0.001 0.001 0.001" />
    <mesh name="arm_link_2_1" content_type="model/stl" file="d:/Programming/RAMI_Project/robot_RAMI_v1_urdf_description/meshes/arm_link_2_1.stl" scale="0.001 0.001 0.001" />
    <mesh name="arm_link_3_1" content_type="model/stl" file="d:/Programming/RAMI_Project/robot_RAMI_v1_urdf_description/meshes/arm_link_3_1.stl" scale="0.001 0.001 0.001" />
    <mesh name="arm_link_4_1" content_type="model/stl" file="d:/Programming/RAMI_Project/robot_RAMI_v1_urdf_description/meshes/arm_link_4_1.stl" scale="0.001 0.001 0.001" />
    <mesh name="arm_link_5_1" content_type="model/stl" file="d:/Programming/RAMI_Project/robot_RAMI_v1_urdf_description/meshes/arm_link_5_1.stl" scale="0.001 0.001 0.001" />
    <mesh name="arm_link_6_1" content_type="model/stl" file="d:/Programming/RAMI_Project/robot_RAMI_v1_urdf_description/meshes/arm_link_6_1.stl" scale="0.001 0.001 0.001" />
    <mesh name="depth_camera_1" content_type="model/stl" file="d:/Programming/RAMI_Project/robot_RAMI_v1_urdf_description/meshes/depth_camera_1.stl" scale="0.001 0.001 0.001" />
    <mesh name="gripper_camera_1" content_type="model/stl" file="d:/Programming/RAMI_Project/robot_RAMI_v1_urdf_description/meshes/gripper_camera_1.stl" scale="0.001 0.001 0.001" />
    <mesh name="ultrasonic_sensor_1_1" content_type="model/stl" file="d:/Programming/RAMI_Project/robot_RAMI_v1_urdf_description/meshes/ultrasonic_sensor_1_1.stl" scale="0.001 0.001 0.001" />
    <mesh name="ultrasonic_sensor_2_1" content_type="model/stl" file="d:/Programming/RAMI_Project/robot_RAMI_v1_urdf_description/meshes/ultrasonic_sensor_2_1.stl" scale="0.001 0.001 0.001" />
    <mesh name="ultrasonic_sensor_3_1" content_type="model/stl" file="d:/Programming/RAMI_Project/robot_RAMI_v1_urdf_description/meshes/ultrasonic_sensor_3_1.stl" scale="0.001 0.001 0.001" />
    <mesh name="ultrasonic_sensor_4_1" content_type="model/stl" file="d:/Programming/RAMI_Project/robot_RAMI_v1_urdf_description/meshes/ultrasonic_sensor_4_1.stl" scale="0.001 0.001 0.001" />
    <mesh name="ultrasonic_sensor_5_1" content_type="model/stl" file="d:/Programming/RAMI_Project/robot_RAMI_v1_urdf_description/meshes/ultrasonic_sensor_5_1.stl" scale="0.001 0.001 0.001" />
    <mesh name="ultrasonic_sensor_6_1" content_type="model/stl" file="d:/Programming/RAMI_Project/robot_RAMI_v1_urdf_description/meshes/ultrasonic_sensor_6_1.stl" scale="0.001 0.001 0.001" />
    <mesh name="ultrasonic_sensor_7_1" content_type="model/stl" file="d:/Programming/RAMI_Project/robot_RAMI_v1_urdf_description/meshes/ultrasonic_sensor_7_1.stl" scale="0.001 0.001 0.001" />
    <mesh name="ultrasonic_sensor_8_1" content_type="model/stl" file="d:/Programming/RAMI_Project/robot_RAMI_v1_urdf_description/meshes/ultrasonic_sensor_8_1.stl" scale="0.001 0.001 0.001" />
    <mesh name="imu_sensor_1" content_type="model/stl" file="d:/Programming/RAMI_Project/robot_RAMI_v1_urdf_description/meshes/imu_sensor_1.stl" scale="0.001 0.001 0.001" />
  </asset>

  <worldbody>
    <!-- 시각적 IK 타겟 마커 (빨간 반투명 구체, mocap 바디로 설정하여 런타임 이동 가능) -->
    <body name="target_marker" pos="0 0 0" mocap="true">
        <geom type="sphere" size="0.05" rgba="1 0 0 0.5" contype="0" conaffinity="0" group="1"/>
    </body>
    <light pos="0 0 3" dir="0 0 -1" directional="true" castshadow="false" />

    <body name="base_link" pos="0 0 0.085">
      <inertial pos="0 0 0.264356" mass="109.995" diaginertia="12.2755 12.1424 1.27632" />
      <joint name="root_x" type="slide" axis="1 0 0" damping="2" frictionloss="0.5" />
      <joint name="root_y" type="slide" axis="0 1 0" damping="2" frictionloss="0.5" />
      <joint name="root_z_rot" type="hinge" axis="0 0 1" damping="2" frictionloss="0.5" />
      <geom type="mesh" mesh="base_link" contype="0" conaffinity="0" />
      <!-- SLAM 벽면 충돌을 위한 베이스 프록시 (바닥과 닿지 않도록 Z 위치를 높임) -->
      <geom type="cylinder" size="0.25 0.3" pos="0 0 0.4" contype="1" conaffinity="1" rgba="0 1 0 0.0" group="3" />
      <geom type="mesh" mesh="pillar_link_1" contype="2" conaffinity="2" />
      <geom type="mesh" mesh="depth_camera_1" contype="0" conaffinity="0" />
      <geom type="mesh" mesh="ultrasonic_sensor_1_1" contype="0" conaffinity="0" />
      <geom type="mesh" mesh="ultrasonic_sensor_2_1" contype="0" conaffinity="0" />
      <geom type="mesh" mesh="ultrasonic_sensor_3_1" contype="0" conaffinity="0" />
      <geom type="mesh" mesh="ultrasonic_sensor_4_1" contype="0" conaffinity="0" />
      <geom type="mesh" mesh="ultrasonic_sensor_5_1" contype="0" conaffinity="0" />
      <geom type="mesh" mesh="ultrasonic_sensor_6_1" contype="0" conaffinity="0" />
      <geom type="mesh" mesh="ultrasonic_sensor_7_1" contype="0" conaffinity="0" />
      <geom type="mesh" mesh="ultrasonic_sensor_8_1" contype="0" conaffinity="0" />
      <geom type="mesh" mesh="imu_sensor_1" contype="0" conaffinity="0" />

      <!-- Sensors on base_link -->
      <camera name="head_camera" pos="0 0 1.515" xyaxes="-1 0 0 0 0 1" fovy="80" />
      <geom name="head_cam_vis" type="mesh" mesh="visual_pyramid_head" pos="0 0 1.515" xyaxes="-1 0 0 0 0 1" material="vis_camera" contype="0" conaffinity="0" group="5" />
      
      <site name="imu_site" pos="0 0 0.055" />
      
      <site name="us_site_1" pos="0.14 -0.14 0.195" zaxis="1 -1 0" />
      <geom name="us_vis_1" type="mesh" mesh="visual_cone_us" pos="0.14 -0.14 0.195" zaxis="1 -1 0" material="vis_ultrasonic" contype="0" conaffinity="0" group="5" />
      
      <site name="us_site_2" pos="0 -0.14 0.195" zaxis="0 -1 0" />
      <geom name="us_vis_2" type="mesh" mesh="visual_cone_us" pos="0 -0.14 0.195" zaxis="0 -1 0" material="vis_ultrasonic" contype="0" conaffinity="0" group="5" />
      
      <site name="us_site_3" pos="-0.14 -0.14 0.195" zaxis="-1 -1 0" />
      <geom name="us_vis_3" type="mesh" mesh="visual_cone_us" pos="-0.14 -0.14 0.195" zaxis="-1 -1 0" material="vis_ultrasonic" contype="0" conaffinity="0" group="5" />
      
      <site name="us_site_4" pos="-0.14 0 0.195" zaxis="-1 0 0" />
      <geom name="us_vis_4" type="mesh" mesh="visual_cone_us" pos="-0.14 0 0.195" zaxis="-1 0 0" material="vis_ultrasonic" contype="0" conaffinity="0" group="5" />
      
      <site name="us_site_5" pos="-0.14 0.14 0.195" zaxis="-1 1 0" />
      <geom name="us_vis_5" type="mesh" mesh="visual_cone_us" pos="-0.14 0.14 0.195" zaxis="-1 1 0" material="vis_ultrasonic" contype="0" conaffinity="0" group="5" />
      
      <site name="us_site_6" pos="0 0.14 0.195" zaxis="0 1 0" />
      <geom name="us_vis_6" type="mesh" mesh="visual_cone_us" pos="0 0.14 0.195" zaxis="0 1 0" material="vis_ultrasonic" contype="0" conaffinity="0" group="5" />
      
      <site name="us_site_7" pos="0.14 0.14 0.195" zaxis="1 1 0" />
      <geom name="us_vis_7" type="mesh" mesh="visual_cone_us" pos="0.14 0.14 0.195" zaxis="1 1 0" material="vis_ultrasonic" contype="0" conaffinity="0" group="5" />
      
      <site name="us_site_8" pos="0.14 0 0.195" zaxis="1 0 0" />
      <geom name="us_vis_8" type="mesh" mesh="visual_cone_us" pos="0.14 0 0.195" zaxis="1 0 0" material="vis_ultrasonic" contype="0" conaffinity="0" group="5" />

      <body name="weel_left_front_1" pos="0.15 -0.1 0.065">
        <inertial pos="-0.0404219 0 0" mass="4.43493" diaginertia="0.006057 0.005355 0.005355" />
        <joint name="weel_LF_joint" pos="0 0 0" axis="1 0 0" damping="0.1" frictionloss="0.01" />
        <geom pos="-0.15 0.1 -0.065" type="mesh" mesh="weel_left_front_1" contype="0" conaffinity="0" />
      </body>
      <body name="weel_left_back_1" pos="0.15 0.1 0.065">
        <inertial pos="-0.0404219 0 0" mass="4.43493" diaginertia="0.006057 0.005355 0.005355" />
        <joint name="weel_LB_joint" pos="0 0 0" axis="1 0 0" damping="0.1" frictionloss="0.01" />
        <geom pos="-0.15 -0.1 -0.065" type="mesh" mesh="weel_left_back_1" contype="0" conaffinity="0" />
      </body>
      <body name="weel_right_front_1" pos="-0.15 -0.1 0.065">
        <inertial pos="0.0404219 0 0" mass="4.43493" diaginertia="0.006057 0.005355 0.005355" />
        <joint name="weel_RF_joint" pos="0 0 0" axis="-1 0 0" damping="0.1" frictionloss="0.01" />
        <geom pos="0.15 0.1 -0.065" type="mesh" mesh="weel_right_front_1" contype="0" conaffinity="0" />
      </body>
      <body name="weel_right_back_1" pos="-0.15 0.1 0.065">
        <inertial pos="0.0404219 0 0" mass="4.43493" diaginertia="0.006057 0.005355 0.005355" />
        <joint name="weel_RB_joint" pos="0 0 0" axis="-1 0 0" damping="0.1" frictionloss="0.01" />
        <geom pos="0.15 -0.1 -0.065" type="mesh" mesh="weel_right_back_1" contype="0" conaffinity="0" />
      </body>
      <body name="lift_slide_link_1" pos="0 -0.02 0.865">
        <inertial pos="0 0.02 0" quat="0.5 0.5 -0.5 0.5" mass="1.6139" diaginertia="0.001693 0.001331 0.001331" />
        <joint name="lift_slide_joint" pos="0 0 0" axis="0 0 1" type="slide" range="-0.62 0.62" actuatorfrcrange="-10000 10000" damping="2000" frictionloss="20" />
        <geom pos="0 0.02 -0.865" quat="1 0 0 0" type="mesh" mesh="lift_slide_link_1" contype="0" conaffinity="0" />
        <body name="rotation_link_1" pos="0 0.02 0.03">
          <inertial pos="0 -0.0110341 -0.03" quat="0.5 0.5 -0.5 0.5" mass="4.89403" diaginertia="0.017752 0.012634 0.008358" />
          <joint name="rotation_joint" pos="0 0 0" axis="0 0 1" range="-3.14159 3.14159" actuatorfrcrange="-1000 1000" damping="50" frictionloss="10" />
          <geom pos="0 0 -0.895" quat="1 0 0 0" type="mesh" mesh="rotation_link_1" />
          <body name="arm_link_1_1" pos="0 -0.1 0">
            <inertial pos="0 -0.03 -0.03" quat="0.707107 0.707107 0 0" mass="2.11686" diaginertia="0.002544 0.002544 0.000873" />
            <joint name="arm_joint_1" pos="0 0 0" axis="0 0 -1" range="-1.5708 1.5708" actuatorfrcrange="-1000 1000" damping="50" frictionloss="10" />
            <geom pos="0 0.1 -0.895" quat="1 0 0 0" type="mesh" mesh="arm_link_1_1" />
            <body name="arm_link_2_1" pos="-0.03 -0.06 -0.03">
              <inertial pos="0.03 -0.110769 0" quat="0.5 0.5 -0.5 0.5" mass="5.47006" diaginertia="0.022162 0.022112 0.003232" />
              <joint name="arm_joint_2" pos="0 0 0" axis="-1 0 0" range="-1.5708 1.5708" actuatorfrcrange="-1000 1000" damping="50" frictionloss="10" />
              <geom pos="0.03 0.16 -0.865" quat="1 0 0 0" type="mesh" mesh="arm_link_2_1" contype="3" conaffinity="3" />
              <body name="arm_link_3_1" pos="0 -0.2 0">
                <inertial pos="0.03 -0.110769 0" quat="0.5 0.5 -0.5 0.5" mass="5.47006" diaginertia="0.022162 0.022112 0.003232" />
                <joint name="arm_joint_3" pos="0 0 0" axis="-1 0 0" range="-1.5708 1.5708" actuatorfrcrange="-1000 1000" damping="50" frictionloss="10" />
                <geom pos="0.03 0.36 -0.865" quat="1 0 0 0" type="mesh" mesh="arm_link_3_1" contype="3" conaffinity="3" />
                <body name="arm_link_4_1" pos="0 -0.2 0">
                  <inertial pos="0.03 -0.0162805 0" quat="0 0.707107 0 0.707107" mass="0.762492" diaginertia="0.000704 0.000593 0.000549" />
                  <joint name="arm_joint_4" pos="0 0 0" axis="-1 0 0" range="-1.5708 1.5708" actuatorfrcrange="-1000 1000" damping="50" frictionloss="10" />
                  <geom pos="0.03 0.56 -0.865" quat="1 0 0 0" type="mesh" mesh="arm_link_4_1" contype="3" conaffinity="3" />
                  <body name="arm_link_5_1" pos="0.03 -0.04 0">
                    <inertial pos="0.000593162 -0.0243798 0.0140847" quat="0.422271 0.905813 0.00466835 -0.0341912" mass="1.24729" diaginertia="0.00130091 0.00103352 0.000791539" />
                    <joint name="arm_joint_5" pos="0 0 0" axis="0 1 0" range="-3.14159 3.14159" actuatorfrcrange="-1000 1000" damping="50" frictionloss="10" />
                    <geom pos="0 0.6 -0.865" type="mesh" mesh="arm_link_5_1" contype="3" conaffinity="3" />
                    <geom pos="0 0.6 -0.865" quat="1 0 0 0" type="mesh" mesh="gripper_camera_1" />
                    
                    <camera name="gripper_camera" pos="0 -0.015 0.05" xyaxes="-1 0 0 0 0 1" fovy="60" />
                    <geom name="gripper_cam_vis" type="mesh" mesh="visual_pyramid_gripper" pos="0 -0.015 0.05" xyaxes="-1 0 0 0 0 1" material="vis_camera" contype="0" conaffinity="0" group="2" />
                    
                    <body name="arm_link_6_1" pos="-0.005 -0.03 -0.015">
                      <inertial pos="0.005 -0.0180282 0.00316455" quat="0.534551 0.462877 -0.462877 0.534551" mass="0.44765" diaginertia="0.0002929 0.000233 0.0001021" />
                      <joint name="arm_joint_6" pos="0 0 0" axis="1 0 0" range="0 1.5708" actuatorfrcrange="-1000 1000" damping="50" frictionloss="10" />
                      <geom pos="0.005 0.63 -0.85" quat="1 0 0 0" type="mesh" mesh="arm_link_6_1" contype="3" conaffinity="3" />
                    </body>
                  </body>
                </body>
              </body>
            </body>
          </body>
        </body>
      </body>
    </body>
  </worldbody>

  <actuator>
    <velocity name="base_vx" joint="root_x" kv="200" ctrlrange="-5 5" />
    <velocity name="base_vy" joint="root_y" kv="200" ctrlrange="-5 5" />
    <velocity name="base_wz" joint="root_z_rot" kv="100" ctrlrange="-5 5" />
    
    <velocity name="weel_lf" joint="weel_LF_joint" kv="2" ctrlrange="-50 50" />
    <velocity name="weel_lb" joint="weel_LB_joint" kv="2" ctrlrange="-50 50" />
    <velocity name="weel_rf" joint="weel_RF_joint" kv="2" ctrlrange="-50 50" />
    <velocity name="weel_rb" joint="weel_RB_joint" kv="2" ctrlrange="-50 50" />

    <!-- 리프트 및 암 조인트 Position Actuator -->
    <position name="act_lift" joint="lift_slide_joint" kp="50000" forcerange="-10000 10000" ctrlrange="-0.62 0.62" />
    <position name="act_rot" joint="rotation_joint" kp="10000" forcerange="-1000 1000" ctrlrange="-3.14159 3.14159" />
    <position name="act_arm1" joint="arm_joint_1" kp="15000" forcerange="-1000 1000" ctrlrange="-1.5708 1.5708" />
    <position name="act_arm2" joint="arm_joint_2" kp="15000" forcerange="-1000 1000" ctrlrange="-1.5708 1.5708" />
    <position name="act_arm3" joint="arm_joint_3" kp="15000" forcerange="-1000 1000" ctrlrange="-1.5708 1.5708" />
    <position name="act_arm4" joint="arm_joint_4" kp="15000" forcerange="-1000 1000" ctrlrange="-1.5708 1.5708" />
    <position name="act_arm5" joint="arm_joint_5" kp="15000" forcerange="-1000 1000" ctrlrange="-3.14159 3.14159" />
    <position name="act_arm6" joint="arm_joint_6" kp="15000" forcerange="-1000 1000" ctrlrange="0 1.5708" />
  </actuator>

  <sensor>
    <accelerometer name="imu_accel" site="imu_site" />
    <gyro name="imu_gyro" site="imu_site" />
    <rangefinder name="ultrasonic_sensor_1" site="us_site_1" />
    <rangefinder name="ultrasonic_sensor_2" site="us_site_2" />
    <rangefinder name="ultrasonic_sensor_3" site="us_site_3" />
    <rangefinder name="ultrasonic_sensor_4" site="us_site_4" />
    <rangefinder name="ultrasonic_sensor_5" site="us_site_5" />
    <rangefinder name="ultrasonic_sensor_6" site="us_site_6" />
    <rangefinder name="ultrasonic_sensor_7" site="us_site_7" />
    <rangefinder name="ultrasonic_sensor_8" site="us_site_8" />
  </sensor>

</mujoco>